[2025-01-12 16:44:25] WARNING Bad Request: /auth/login/
[2025-01-12 16:50:20] WARNING Not Found: /api/orders.
[2025-01-12 16:50:22] WARNING Bad Request: /api/orders/
[2025-01-12 17:19:13] WARNING Method Not Allowed: /auth/login/
[2025-01-12 17:19:40] WARNING Bad Request: /api/orders/
[2025-01-12 17:33:00] WARNING Forbidden: /api/orders/6/
[2025-01-12 17:39:33] WARNING Not Found: /api/orders.
[2025-01-12 17:39:35] ERROR Internal Server Error: /api/orders/
Traceback (most recent call last):
  File "/usr/local/lib/python3.11/site-packages/django/core/handlers/exception.py", line 55, in inner
    response = get_response(request)
               ^^^^^^^^^^^^^^^^^^^^^
  File "/usr/local/lib/python3.11/site-packages/django/core/handlers/base.py", line 197, in _get_response
    response = wrapped_callback(request, *callback_args, **callback_kwargs)
               ^^^^^^^^^^^^^^^^^^^^^^^^^^^^^^^^^^^^^^^^^^^^^^^^^^^^^^^^^^^^
  File "/usr/local/lib/python3.11/site-packages/django/views/decorators/csrf.py", line 65, in _view_wrapper
    return view_func(request, *args, **kwargs)
           ^^^^^^^^^^^^^^^^^^^^^^^^^^^^^^^^^^^
  File "/usr/local/lib/python3.11/site-packages/django/views/generic/base.py", line 104, in view
    return self.dispatch(request, *args, **kwargs)
           ^^^^^^^^^^^^^^^^^^^^^^^^^^^^^^^^^^^^^^^
  File "/usr/local/lib/python3.11/site-packages/rest_framework/views.py", line 509, in dispatch
    response = self.handle_exception(exc)
               ^^^^^^^^^^^^^^^^^^^^^^^^^^
  File "/usr/local/lib/python3.11/site-packages/rest_framework/views.py", line 469, in handle_exception
    self.raise_uncaught_exception(exc)
  File "/usr/local/lib/python3.11/site-packages/rest_framework/views.py", line 480, in raise_uncaught_exception
    raise exc
  File "/usr/local/lib/python3.11/site-packages/rest_framework/views.py", line 506, in dispatch
    response = handler(request, *args, **kwargs)
               ^^^^^^^^^^^^^^^^^^^^^^^^^^^^^^^^^
  File "/app/myproject/api/views/orders.py", line 130, in delete
    order_id = kwargs['id']
               ~~~~~~^^^^^^
KeyError: 'id'
[2025-01-12 17:42:40] WARNING Not Found: /
[2025-01-12 17:46:48] WARNING Forbidden: /api/orders/4/
[2025-01-12 18:35:06] WARNING Unauthorized: /api/orders/6/
[2025-01-12 22:21:41] WARNING Not Found: /
[2025-01-12 22:30:08] WARNING Unauthorized: /api/orders/6/
[2025-01-12 22:30:13] WARNING Unauthorized: /api/orders/
[2025-01-12 22:30:20] WARNING Unauthorized: /api/orders/
[2025-01-12 23:01:12] WARNING Not Found: /
[2025-01-12 23:09:52] WARNING Not Found: /
[2025-01-12 23:29:37] WARNING Not Found: /
[2025-01-12 23:29:37] WARNING Not Found: /favicon.ico
[2025-01-13 10:44:32] WARNING Not Found: /
[2025-01-13 10:46:04] WARNING Not Found: /docs/swaggger
[2025-01-13 10:46:06] WARNING Not Found: /docs/swaggger/
[2025-01-13 10:46:12] WARNING Not Found: /static/drf-yasg/style.css
[2025-01-13 10:46:12] WARNING Not Found: /static/drf-yasg/swagger-ui-dist/swagger-ui.css
[2025-01-13 10:46:12] WARNING Not Found: /static/drf-yasg/swagger-ui-dist/swagger-ui-bundle.js
[2025-01-13 10:46:12] WARNING Not Found: /static/drf-yasg/swagger-ui-dist/swagger-ui-standalone-preset.js
[2025-01-13 10:46:12] WARNING Not Found: /static/drf-yasg/insQ.min.js
[2025-01-13 10:46:12] WARNING Not Found: /static/drf-yasg/swagger-ui-init.js
[2025-01-13 10:46:12] WARNING Not Found: /static/drf-yasg/immutable.min.js
[2025-01-13 10:46:12] WARNING Not Found: /static/drf-yasg/swagger-ui-dist/favicon-32x32.png
[2025-01-13 10:46:14] WARNING Not Found: /accounts/login/
[2025-01-13 10:47:03] WARNING Not Found: /static/drf-yasg/style.css
[2025-01-13 10:47:03] WARNING Not Found: /static/drf-yasg/swagger-ui-dist/swagger-ui-bundle.js
[2025-01-13 10:47:03] WARNING Not Found: /static/drf-yasg/swagger-ui-dist/swagger-ui.css
[2025-01-13 10:47:03] WARNING Not Found: /static/drf-yasg/swagger-ui-dist/swagger-ui-standalone-preset.js
[2025-01-13 10:47:03] WARNING Not Found: /static/drf-yasg/insQ.min.js
[2025-01-13 10:47:03] WARNING Not Found: /static/drf-yasg/immutable.min.js
[2025-01-13 10:47:03] WARNING Not Found: /static/drf-yasg/swagger-ui-init.js
[2025-01-13 10:59:30] WARNING Not Found: /static/drf-yasg/swagger-ui-dist/swagger-ui.css
[2025-01-13 10:59:30] WARNING Not Found: /static/drf-yasg/style.css
[2025-01-13 10:59:30] WARNING Not Found: /static/drf-yasg/swagger-ui-dist/swagger-ui-standalone-preset.js
[2025-01-13 10:59:30] WARNING Not Found: /static/drf-yasg/insQ.min.js
[2025-01-13 10:59:30] WARNING Not Found: /static/drf-yasg/swagger-ui-dist/swagger-ui-bundle.js
[2025-01-13 10:59:30] WARNING Not Found: /static/drf-yasg/immutable.min.js
[2025-01-13 10:59:30] WARNING Not Found: /static/drf-yasg/swagger-ui-init.js
[2025-01-13 11:01:07] WARNING Not Found: /api/orders/1/
[2025-01-13 11:02:04] WARNING Bad Request: /auth/login/
[2025-01-13 11:02:26] WARNING Bad Request: /auth/login/
[2025-01-13 11:03:01] WARNING Bad Request: /auth/login/
[2025-01-13 11:04:26] WARNING Bad Request: /auth/login/
[2025-01-13 11:04:42] WARNING Not Found: /auth/login
[2025-01-13 11:04:45] WARNING Bad Request: /auth/login/
[2025-01-13 11:04:52] WARNING Bad Request: /auth/login/
[2025-01-13 11:05:24] WARNING Bad Request: /auth/login/
[2025-01-13 11:06:41] WARNING Bad Request: /auth/login/
[2025-01-13 11:08:16] WARNING Bad Request: /auth/login/
[2025-01-13 11:17:51] WARNING Not Found: /accounts/login/
[2025-01-13 11:19:00] WARNING Unauthorized: /api/orders/
[2025-01-13 11:22:11] WARNING Unauthorized: /api/orders/1/
[2025-01-13 11:29:19] WARNING Unauthorized: /api/orders/
[2025-01-13 11:47:39] WARNING Forbidden: /api/orders/1/
[2025-01-13 12:05:15] WARNING Unauthorized: /api/orders/1/
[2025-01-13 12:05:39] WARNING Bad Request: /api/orders/1/
[2025-01-13 12:06:14] ERROR Internal Server Error: /api/orders/1/
Traceback (most recent call last):
  File "/usr/local/lib/python3.11/site-packages/django/core/handlers/exception.py", line 55, in inner
    response = get_response(request)
               ^^^^^^^^^^^^^^^^^^^^^
  File "/usr/local/lib/python3.11/site-packages/django/core/handlers/base.py", line 197, in _get_response
    response = wrapped_callback(request, *callback_args, **callback_kwargs)
               ^^^^^^^^^^^^^^^^^^^^^^^^^^^^^^^^^^^^^^^^^^^^^^^^^^^^^^^^^^^^
  File "/usr/local/lib/python3.11/site-packages/django/views/decorators/csrf.py", line 65, in _view_wrapper
    return view_func(request, *args, **kwargs)
           ^^^^^^^^^^^^^^^^^^^^^^^^^^^^^^^^^^^
  File "/usr/local/lib/python3.11/site-packages/django/views/generic/base.py", line 104, in view
    return self.dispatch(request, *args, **kwargs)
           ^^^^^^^^^^^^^^^^^^^^^^^^^^^^^^^^^^^^^^^
  File "/usr/local/lib/python3.11/site-packages/rest_framework/views.py", line 509, in dispatch
    response = self.handle_exception(exc)
               ^^^^^^^^^^^^^^^^^^^^^^^^^^
  File "/usr/local/lib/python3.11/site-packages/rest_framework/views.py", line 469, in handle_exception
    self.raise_uncaught_exception(exc)
  File "/usr/local/lib/python3.11/site-packages/rest_framework/views.py", line 480, in raise_uncaught_exception
    raise exc
  File "/usr/local/lib/python3.11/site-packages/rest_framework/views.py", line 506, in dispatch
    response = handler(request, *args, **kwargs)
               ^^^^^^^^^^^^^^^^^^^^^^^^^^^^^^^^^
  File "/app/myproject/api/views/orders.py", line 125, in patch
    cache.set(cache_key, serializer.data, timeout=300)
                         ^^^^^^^^^^^^^^^
  File "/usr/local/lib/python3.11/site-packages/rest_framework/serializers.py", line 571, in data
    ret = super().data
          ^^^^^^^^^^^^
  File "/usr/local/lib/python3.11/site-packages/rest_framework/serializers.py", line 249, in data
    self._data = self.to_representation(self.instance)
                 ^^^^^^^^^^^^^^^^^^^^^^^^^^^^^^^^^^^^^
  File "/usr/local/lib/python3.11/site-packages/rest_framework/serializers.py", line 538, in to_representation
    ret[field.field_name] = field.to_representation(attribute)
                            ^^^^^^^^^^^^^^^^^^^^^^^^^^^^^^^^^^
  File "/usr/local/lib/python3.11/site-packages/rest_framework/fields.py", line 1096, in to_representation
    quantized = self.quantize(value)
                ^^^^^^^^^^^^^^^^^^^^
  File "/usr/local/lib/python3.11/site-packages/rest_framework/fields.py", line 1118, in quantize
    return value.quantize(
           ^^^^^^^^^^^^^^^
decimal.InvalidOperation: [<class 'decimal.InvalidOperation'>]
[2025-01-13 12:06:36] ERROR Internal Server Error: /api/orders/1/
Traceback (most recent call last):
  File "/usr/local/lib/python3.11/site-packages/django/core/handlers/exception.py", line 55, in inner
    response = get_response(request)
               ^^^^^^^^^^^^^^^^^^^^^
  File "/usr/local/lib/python3.11/site-packages/django/core/handlers/base.py", line 197, in _get_response
    response = wrapped_callback(request, *callback_args, **callback_kwargs)
               ^^^^^^^^^^^^^^^^^^^^^^^^^^^^^^^^^^^^^^^^^^^^^^^^^^^^^^^^^^^^
  File "/usr/local/lib/python3.11/site-packages/django/views/decorators/csrf.py", line 65, in _view_wrapper
    return view_func(request, *args, **kwargs)
           ^^^^^^^^^^^^^^^^^^^^^^^^^^^^^^^^^^^
  File "/usr/local/lib/python3.11/site-packages/django/views/generic/base.py", line 104, in view
    return self.dispatch(request, *args, **kwargs)
           ^^^^^^^^^^^^^^^^^^^^^^^^^^^^^^^^^^^^^^^
  File "/usr/local/lib/python3.11/site-packages/rest_framework/views.py", line 509, in dispatch
    response = self.handle_exception(exc)
               ^^^^^^^^^^^^^^^^^^^^^^^^^^
  File "/usr/local/lib/python3.11/site-packages/rest_framework/views.py", line 469, in handle_exception
    self.raise_uncaught_exception(exc)
  File "/usr/local/lib/python3.11/site-packages/rest_framework/views.py", line 480, in raise_uncaught_exception
    raise exc
  File "/usr/local/lib/python3.11/site-packages/rest_framework/views.py", line 506, in dispatch
    response = handler(request, *args, **kwargs)
               ^^^^^^^^^^^^^^^^^^^^^^^^^^^^^^^^^
  File "/app/myproject/api/views/orders.py", line 125, in patch
    cache.set(cache_key, serializer.data, timeout=300)
                         ^^^^^^^^^^^^^^^
  File "/usr/local/lib/python3.11/site-packages/rest_framework/serializers.py", line 571, in data
    ret = super().data
          ^^^^^^^^^^^^
  File "/usr/local/lib/python3.11/site-packages/rest_framework/serializers.py", line 249, in data
    self._data = self.to_representation(self.instance)
                 ^^^^^^^^^^^^^^^^^^^^^^^^^^^^^^^^^^^^^
  File "/usr/local/lib/python3.11/site-packages/rest_framework/serializers.py", line 538, in to_representation
    ret[field.field_name] = field.to_representation(attribute)
                            ^^^^^^^^^^^^^^^^^^^^^^^^^^^^^^^^^^
  File "/usr/local/lib/python3.11/site-packages/rest_framework/fields.py", line 1096, in to_representation
    quantized = self.quantize(value)
                ^^^^^^^^^^^^^^^^^^^^
  File "/usr/local/lib/python3.11/site-packages/rest_framework/fields.py", line 1118, in quantize
    return value.quantize(
           ^^^^^^^^^^^^^^^
decimal.InvalidOperation: [<class 'decimal.InvalidOperation'>]
[2025-01-13 12:07:11] WARNING Forbidden: /api/orders/1/
[2025-01-13 12:07:56] WARNING Unauthorized: /api/orders/1/
[2025-01-13 12:18:02] WARNING Bad Request: /api/orders/
[2025-01-13 12:27:44] ERROR Internal Server Error: /api/orders/
Traceback (most recent call last):
  File "/usr/local/lib/python3.11/site-packages/django/core/handlers/exception.py", line 55, in inner
    response = get_response(request)
               ^^^^^^^^^^^^^^^^^^^^^
  File "/usr/local/lib/python3.11/site-packages/django/core/handlers/base.py", line 197, in _get_response
    response = wrapped_callback(request, *callback_args, **callback_kwargs)
               ^^^^^^^^^^^^^^^^^^^^^^^^^^^^^^^^^^^^^^^^^^^^^^^^^^^^^^^^^^^^
  File "/usr/local/lib/python3.11/site-packages/django/views/decorators/csrf.py", line 65, in _view_wrapper
    return view_func(request, *args, **kwargs)
           ^^^^^^^^^^^^^^^^^^^^^^^^^^^^^^^^^^^
  File "/usr/local/lib/python3.11/site-packages/django/views/generic/base.py", line 104, in view
    return self.dispatch(request, *args, **kwargs)
           ^^^^^^^^^^^^^^^^^^^^^^^^^^^^^^^^^^^^^^^
  File "/usr/local/lib/python3.11/site-packages/rest_framework/views.py", line 509, in dispatch
    response = self.handle_exception(exc)
               ^^^^^^^^^^^^^^^^^^^^^^^^^^
  File "/usr/local/lib/python3.11/site-packages/rest_framework/views.py", line 469, in handle_exception
    self.raise_uncaught_exception(exc)
  File "/usr/local/lib/python3.11/site-packages/rest_framework/views.py", line 480, in raise_uncaught_exception
    raise exc
  File "/usr/local/lib/python3.11/site-packages/rest_framework/views.py", line 506, in dispatch
    response = handler(request, *args, **kwargs)
               ^^^^^^^^^^^^^^^^^^^^^^^^^^^^^^^^^
  File "/app/myproject/api/views/orders.py", line 114, in patch
    order_id = kwargs['id']
               ~~~~~~^^^^^^
KeyError: 'id'
[2025-01-13 12:27:54] WARNING Forbidden: /api/orders/2/
